Workbook

Sheet Расчет грейда
L2: Опознавательные цвета
M4: Логичное сочетание
M6: Менее вероятное сочение | R6: А
R7: ИТ
M8: Нелогичное сочетание | R8: КЦ
M10: Невозможное сочетание
BE12: Техническая поддержка, Финдир, Директор по информационным технологиям, Директор по продукту,
J16: 1 | M16: 2 | O16: 3
J17: 1. Данные из паспорта "Знания и умения" | M17: 2. Данные из паспорта "Решение вопросов" | O17: 3. Данные из паспорта "Ответственность" | T17: Если модификатор НЕ меняем на (-) или (+), оставляем ячейку пустой | X17: Технические столбцы для расчета знаний и умений | AA17: Технические столбцы для расчета решения вопросов | AD17: Технические столбцы для расчета ответственности | AG17: Технические столбцы для расчета итоговой формулы | AT17: Технические столбцы для расчета профиля | AV17: 1. Подсчет баллов "Знания и умения" | AW17: 2. Подсчет баллов "Решение вопросов" | AY17: 3. Подсчет баллов "Ответственность" | BA17: Результат показывает, есть ли куда расти относительно вилки баллов | BB17: Профили больше А3 и P4 говорят о сомнительных результатах. Необходимо проверить, является ли такое представление дожности достоверным
A18: Книга | B18: Номер паспорта | C18: Номер Роли | D18: 1 | E18: 2 | F18: 3 | G18: 4 | H18: 5 | I18: Должность | J18: Необходимые умения (10 вопрос) | K18: Умение планировать, организовывать (9 вопрос) | L18: Взаимодействие и коммуникация (8 вопрос) | M18: Область решаемых вопросов (11 вопрос) | N18: Сложность решаемых вопросов (12 вопрос) | O18: Свобода действий должности (16 вопрос) | P18: Величина воздействия (13 вопрос) | Q18: Тип влияния (14 вопрос) | R18: Атрибут | S18: Оклад | T18: Модиф. умения | U18: Модиф. Решение вопросов | V18: Модиф. Свобода д-й | W18: Грейд Sber | X18: Сцепка | Y18: Модификатор | Z18: Цвет | AA18: Модификатор | AB18: Цвет по проценту | AC18: Цвет по баллу | AD18: Сцепка | AE18: Модификатор | AF18: Цвет | AG18: Необходимые умения кратко | AH18: Умение планировать, организовывать кратко | AI18: Взаимодействие и коммуникация кратко | AJ18: Знания и умения балл | AK18: Область решаемых вопросов кратко | AL18: Сложность решаемых вопросов кратко | AM18: Степень владения процессом кратко | AN18: Решение вопросов балл | AO18: Свобода действий | AP18: Величина воздействия | AQ18: Тип влияния | AR18: Баллы ответственность | AS18: Балл итог | AT18: Профиль | AU18: Число шагов | AV18: Модиф. умения | AW18: Модиф. Решение вопросов | AX18: Модиф. Решение вопросов | AY18: Модиф. Свобода д-й | AZ18: ИТОГО | BA18: Баллы относительно медианы | BB18: Тип должности | BC18: Профиль с количеством шагов | BD18: Комментарий к профилю | BE18: Итоговая формула оценки | BF18: Грейд по HAY
W19: =IF(IFERROR(BF19-6,"")<0,0,IFERROR(BF19-6,"")) | X19: =CONCATENATE(K19,L19) | Y19: =CONCATENATE(J19,T19) | Z19: =INDEX('справочная информация'!$U$6:$AK$29,MATCH('Расчет грейда'!$Y19,'справочная информация'!$T$6:$T$29,0),MATCH('Расчет грейда'!$X19,'справочная информация'!$U$5:$AK$5,0)) -> #N/A | AA19: =CONCATENATE(M19,U19) | AB19: =INDEX('справочная информация'!$B$68:$H$83,MATCH('Расчет грейда'!$AA19,'справочная информация'!$A$68:$A$83,0),MATCH('Расчет грейда'!$N19,'справочная информация'!$B$67:$H$67,0)) -> #N/A | AC19: =INDEX('справочная информация'!$D$130:$AD$145,MATCH('Расчет грейда'!$AW19,'справочная информация'!$C$130:$C$145,0),MATCH('Расчет грейда'!$AV19,'справочная информация'!$D$129:$AD$129,0)) -> #N/A | AD19: =CONCATENATE(P19,Q19) | AE19: =CONCATENATE(O19,V19) | AF19: =IFERROR(IF(AND(AD19="",AE19=""),"",INDEX('справочная информация'!$B$188:$Y$211,MATCH('Расчет грейда'!$AE19,'справочная информация'!$A$188:$A$211,0),MATCH('Расчет грейда'!$AD19,'справочная информация'!$B$187:$Y$187,0))),"НЕТ") | AG19: =VLOOKUP(J19,'справочная информация'!$D$267:$E$274,2,0) -> #N/A | AH19: =VLOOKUP(K19,'справочная информация'!$D$279:$E$283,2,0) -> #N/A | AI19: =VLOOKUP(L19,'справочная информация'!$D$288:$E$290,2,0) -> #N/A | AJ19: =AV19 | AK19: =VLOOKUP(M19,'справочная информация'!$D$294:$E$301,2,0) -> #N/A | AL19: =VLOOKUP(N19,'справочная информация'!$D$306:$E$310,2,0) -> #N/A | AM19: =CONCATENATE("(",AW19,")") -> () | AN19: =AX19 | AO19: =VLOOKUP(O19,'справочная информация'!$D$329:$E$336,2,0) -> #N/A | AP19: =VLOOKUP(P19,'справочная информация'!$D$342:$E$349,2,0) -> #N/A | AQ19: =VLOOKUP(Q19,'справочная информация'!$D$316:$E$325,2,0) -> #N/A | AR19: =AY19 | AS19: =AZ19 | AT19: =IF(AND(AX19="",AY19=""),"",IF(AY19>AX19,"A",IF(AX19=AY19,"L","P"))) | AU19: =ABS(MATCH($AX19,'справочная информация'!$A$354:$A$391,0)-MATCH($AY19,'справочная информация'!$A$354:$A$391,0)) -> #N/A | AV19: =IFERROR(INDEX('справочная информация'!$B$6:$R$29,MATCH('Расчет грейда'!$Y19,'справочная информация'!$A$6:$A$29,0),MATCH('Расчет грейда'!$X19,'справочная информация'!$B$5:$R$5,0)),"") | AW19: =IFERROR(INDEX('справочная информация'!$B$37:$H$52,MATCH('Расчет грейда'!$AA19,'справочная информация'!$A$37:$A$52,0),MATCH('Расчет грейда'!$N19,'справочная информация'!$B$36:$H$36,0)),"") | AX19: =IFERROR(INDEX('справочная информация'!$D$108:$AD$123,MATCH('Расчет грейда'!$AW19,'справочная информация'!$C$108:$C$123,0),MATCH('Расчет грейда'!$AV19,'справочная информация'!$D$107:$AD$107,0)),"") | AY19: =IFERROR(INDEX('справочная информация'!$B$158:$Y$181,MATCH('Расчет грейда'!$AE19,'справочная информация'!$A$158:$A$181,0),MATCH('Расчет грейда'!$AD19,'справочная информация'!$B$157:$Y$157,0)),"") | AZ19: =IFERROR(AV19+AX19+AY19,"") | BA19: =IFERROR(CONCATENATE(TEXT(AZ19/INDEX('справочная информация'!$D$223:$D$261,MATCH('Расчет грейда'!$AZ19,'справочная информация'!$C$223:$C$261,1)),"0%")," - процент относительно медианы 100%. ","MIN балл на грейде ",INDEX('справочная информация'!$C$223:$C$261,MATCH('Расчет грейда'!$AZ19,'справочная информация'!$C$223:$C$261,1)),", "," MAX балл на грейде ",INDEX('справочная информация'!$E$223:$E$261,MATCH('Расчет грейда'!$AZ19,'справочная информация'!$C$223:$C$261,1))),"") | BB19: =IFERROR(IF(AND(AX19="",AY19=""),"",IF(AY19>AX19,"Ответственный профиль (ACC)",IF(AY19=AX19,"Профиль равный (L)","Профиль решения вопросов (PS)"))),"") | BC19: =IFERROR(CONCATENATE(AT19,AU19),"") | BD19: =IFERROR(VLOOKUP(BC19,'справочная информация'!$B$416:$C$424,2,0),"Проверить данные, нетипичная должность") -> Проверить данные, нетипичная должность | BE19: =IFERROR(CONCATENATE(AG19,AH19,AI19," ",AJ19," ",AK19,AL19," ",AM19," ",AN19," ",AO19,AP19,AQ19," ",AR19," ",AS19," ",BC19),"") | BF19: =IFERROR(INDEX('справочная информация'!$F$223:$F$261,MATCH('Расчет грейда'!$AZ19,'справочная информация'!$C$223:$C$261,1)),"")
W20: =IF(IFERROR(BF20-6,"")<0,0,IFERROR(BF20-6,"")) | X20: =CONCATENATE(K20,L20) | Y20: =CONCATENATE(J20,T20) | Z20: =INDEX('справочная информация'!$U$6:$AK$29,MATCH('Расчет грейда'!$Y20,'справочная информация'!$T$6:$T$29,0),MATCH('Расчет грейда'!$X20,'справочная информация'!$U$5:$AK$5,0)) -> #N/A | AA20: =CONCATENATE(M20,U20) | AB20: =INDEX('справочная информация'!$B$68:$H$83,MATCH('Расчет грейда'!$AA20,'справочная информация'!$A$68:$A$83,0),MATCH('Расчет грейда'!$N20,'справочная информация'!$B$67:$H$67,0)) -> #N/A | AC20: =INDEX('справочная информация'!$D$130:$AD$145,MATCH('Расчет грейда'!$AW20,'справочная информация'!$C$130:$C$145,0),MATCH('Расчет грейда'!$AV20,'справочная информация'!$D$129:$AD$129,0)) -> #N/A | AD20: =CONCATENATE(P20,Q20) | AE20: =CONCATENATE(O20,V20) | AF20: =IFERROR(IF(AND(AD20="",AE20=""),"",INDEX('справочная информация'!$B$188:$Y$211,MATCH('Расчет грейда'!$AE20,'справочная информация'!$A$188:$A$211,0),MATCH('Расчет грейда'!$AD20,'справочная информация'!$B$187:$Y$187,0))),"НЕТ") | AG20: =VLOOKUP(J20,'справочная информация'!$D$267:$E$274,2,0) -> #N/A | AH20: =VLOOKUP(K20,'справочная информация'!$D$279:$E$283,2,0) -> #N/A | AI20: =VLOOKUP(L20,'справочная информация'!$D$288:$E$290,2,0) -> #N/A | AJ20: =AV20 | AK20: =VLOOKUP(M20,'справочная информация'!$D$294:$E$301,2,0) -> #N/A | AL20: =VLOOKUP(N20,'справочная информация'!$D$306:$E$310,2,0) -> #N/A | AM20: =CONCATENATE("(",AW20,")") -> () | AN20: =AX20 | AO20: =VLOOKUP(O20,'справочная информация'!$D$329:$E$336,2,0) -> #N/A | AP20: =VLOOKUP(P20,'справочная информация'!$D$342:$E$349,2,0) -> #N/A | AQ20: =VLOOKUP(Q20,'справочная информация'!$D$316:$E$325,2,0) -> #N/A | AR20: =AY20 | AS20: =AZ20 | AT20: =IF(AND(AX20="",AY20=""),"",IF(AY20>AX20,"A",IF(AX20=AY20,"L","P"))) | AU20: =ABS(MATCH($AX20,'справочная информация'!$A$354:$A$391,0)-MATCH($AY20,'справочная информация'!$A$354:$A$391,0)) -> #N/A | AV20: =IFERROR(INDEX('справочная информация'!$B$6:$R$29,MATCH('Расчет грейда'!$Y20,'справочная информация'!$A$6:$A$29,0),MATCH('Расчет грейда'!$X20,'справочная информация'!$B$5:$R$5,0)),"") | AW20: =IFERROR(INDEX('справочная информация'!$B$37:$H$52,MATCH('Расчет грейда'!$AA20,'справочная информация'!$A$37:$A$52,0),MATCH('Расчет грейда'!$N20,'справочная информация'!$B$36:$H$36,0)),"") | AX20: =IFERROR(INDEX('справочная информация'!$D$108:$AD$123,MATCH('Расчет грейда'!$AW20,'справочная информация'!$C$108:$C$123,0),MATCH('Расчет грейда'!$AV20,'справочная информация'!$D$107:$AD$107,0)),"") | AY20: =IFERROR(INDEX('справочная информация'!$B$158:$Y$181,MATCH('Расчет грейда'!$AE20,'справочная информация'!$A$158:$A$181,0),MATCH('Расчет грейда'!$AD20,'справочная информация'!$B$157:$Y$157,0)),"") | AZ20: =IFERROR(AV20+AX20+AY20,"") | BA20: =IFERROR(CONCATENATE(TEXT(AZ20/INDEX('справочная информация'!$D$223:$D$261,MATCH('Расчет грейда'!$AZ20,'справочная информация'!$C$223:$C$261,1)),"0%")," - процент относительно медианы 100%. ","MIN балл на грейде ",INDEX('справочная информация'!$C$223:$C$261,MATCH('Расчет грейда'!$AZ20,'справочная информация'!$C$223:$C$261,1)),", "," MAX балл на грейде ",INDEX('справочная информация'!$E$223:$E$261,MATCH('Расчет грейда'!$AZ20,'справочная информация'!$C$223:$C$261,1))),"") | BB20: =IFERROR(IF(AND(AX20="",AY20=""),"",IF(AY20>AX20,"Ответственный профиль (ACC)",IF(AY20=AX20,"Профиль равный (L)","Профиль решения вопросов (PS)"))),"") | BC20: =IFERROR(CONCATENATE(AT20,AU20),"") | BD20: =IFERROR(VLOOKUP(BC20,'справочная информация'!$B$416:$C$424,2,0),"Проверить данные, нетипичная должность") -> Проверить данные, нетипичная должность | BE20: =IFERROR(CONCATENATE(AG20,AH20,AI20," ",AJ20," ",AK20,AL20," ",AM20," ",AN20," ",AO20,AP20,AQ20," ",AR20," ",AS20," ",BC20),"") | BF20: =IFERROR(INDEX('справочная информация'!$F$223:$F$261,MATCH('Расчет грейда'!$AZ20,'справочная информация'!$C$223:$C$261,1)),"")
W21: =IF(IFERROR(BF21-6,"")<0,0,IFERROR(BF21-6,"")) | X21: =CONCATENATE(K21,L21) | Y21: =CONCATENATE(J21,T21) | Z21: =INDEX('справочная информация'!$U$6:$AK$29,MATCH('Расчет грейда'!$Y21,'справочная информация'!$T$6:$T$29,0),MATCH('Расчет грейда'!$X21,'справочная информация'!$U$5:$AK$5,0)) -> #N/A | AA21: =CONCATENATE(M21,U21) | AB21: =INDEX('справочная информация'!$B$68:$H$83,MATCH('Расчет грейда'!$AA21,'справочная информация'!$A$68:$A$83,0),MATCH('Расчет грейда'!$N21,'справочная информация'!$B$67:$H$67,0)) -> #N/A | AC21: =INDEX('справочная информация'!$D$130:$AD$145,MATCH('Расчет грейда'!$AW21,'справочная информация'!$C$130:$C$145,0),MATCH('Расчет грейда'!$AV21,'справочная информация'!$D$129:$AD$129,0)) -> #N/A | AD21: =CONCATENATE(P21,Q21) | AE21: =CONCATENATE(O21,V21) | AF21: =IFERROR(IF(AND(AD21="",AE21=""),"",INDEX('справочная информация'!$B$188:$Y$211,MATCH('Расчет грейда'!$AE21,'справочная информация'!$A$188:$A$211,0),MATCH('Расчет грейда'!$AD21,'справочная информация'!$B$187:$Y$187,0))),"НЕТ") | AG21: =VLOOKUP(J21,'справочная информация'!$D$267:$E$274,2,0) -> #N/A | AH21: =VLOOKUP(K21,'справочная информация'!$D$279:$E$283,2,0) -> #N/A | AI21: =VLOOKUP(L21,'справочная информация'!$D$288:$E$290,2,0) -> #N/A | AJ21: =AV21 | AK21: =VLOOKUP(M21,'справочная информация'!$D$294:$E$301,2,0) -> #N/A | AL21: =VLOOKUP(N21,'справочная информация'!$D$306:$E$310,2,0) -> #N/A | AM21: =CONCATENATE("(",AW21,")") -> () | AN21: =AX21 | AO21: =VLOOKUP(O21,'справочная информация'!$D$329:$E$336,2,0) -> #N/A | AP21: =VLOOKUP(P21,'справочная информация'!$D$342:$E$349,2,0) -> #N/A | AQ21: =VLOOKUP(Q21,'справочная информация'!$D$316:$E$325,2,0) -> #N/A | AR21: =AY21 | AS21: =AZ21 | AT21: =IF(AND(AX21="",AY21=""),"",IF(AY21>AX21,"A",IF(AX21=AY21,"L","P"))) | AU21: =ABS(MATCH($AX21,'справочная информация'!$A$354:$A$391,0)-MATCH($AY21,'справочная информация'!$A$354:$A$391,0)) -> #N/A | AV21: =IFERROR(INDEX('справочная информация'!$B$6:$R$29,MATCH('Расчет грейда'!$Y21,'справочная информация'!$A$6:$A$29,0),MATCH('Расчет грейда'!$X21,'справочная информация'!$B$5:$R$5,0)),"") | AW21: =IFERROR(INDEX('справочная информация'!$B$37:$H$52,MATCH('Расчет грейда'!$AA21,'справочная информация'!$A$37:$A$52,0),MATCH('Расчет грейда'!$N21,'справочная информация'!$B$36:$H$36,0)),"") | AX21: =IFERROR(INDEX('справочная информация'!$D$108:$AD$123,MATCH('Расчет грейда'!$AW21,'справочная информация'!$C$108:$C$123,0),MATCH('Расчет грейда'!$AV21,'справочная информация'!$D$107:$AD$107,0)),"") | AY21: =IFERROR(INDEX('справочная информация'!$B$158:$Y$181,MATCH('Расчет грейда'!$AE21,'справочная информация'!$A$158:$A$181,0),MATCH('Расчет грейда'!$AD21,'справочная информация'!$B$157:$Y$157,0)),"") | AZ21: =IFERROR(AV21+AX21+AY21,"") | BA21: =IFERROR(CONCATENATE(TEXT(AZ21/INDEX('справочная информация'!$D$223:$D$261,MATCH('Расчет грейда'!$AZ21,'справочная информация'!$C$223:$C$261,1)),"0%")," - процент относительно медианы 100%. ","MIN балл на грейде ",INDEX('справочная информация'!$C$223:$C$261,MATCH('Расчет грейда'!$AZ21,'справочная информация'!$C$223:$C$261,1)),", "," MAX балл на грейде ",INDEX('справочная информация'!$E$223:$E$261,MATCH('Расчет грейда'!$AZ21,'справочная информация'!$C$223:$C$261,1))),"") | BB21: =IFERROR(IF(AND(AX21="",AY21=""),"",IF(AY21>AX21,"Ответственный профиль (ACC)",IF(AY21=AX21,"Профиль равный (L)","Профиль решения вопросов (PS)"))),"") | BC21: =IFERROR(CONCATENATE(AT21,AU21),"") | BD21: =IFERROR(VLOOKUP(BC21,'справочная информация'!$B$416:$C$424,2,0),"Проверить данные, нетипичная должность") -> Проверить данные, нетипичная должность | BE21: =IFERROR(CONCATENATE(AG21,AH21,AI21," ",AJ21," ",AK21,AL21," ",AM21," ",AN21," ",AO21,AP21,AQ21," ",AR21," ",AS21," ",BC21),"") | BF21: =IFERROR(INDEX('справочная информация'!$F$223:$F$261,MATCH('Расчет грейда'!$AZ21,'справочная информация'!$C$223:$C$261,1)),"")
W22: =IF(IFERROR(BF22-6,"")<0,0,IFERROR(BF22-6,"")) | X22: =CONCATENATE(K22,L22) | Y22: =CONCATENATE(J22,T22) | Z22: =INDEX('справочная информация'!$U$6:$AK$29,MATCH('Расчет грейда'!$Y22,'справочная информация'!$T$6:$T$29,0),MATCH('Расчет грейда'!$X22,'справочная информация'!$U$5:$AK$5,0)) -> #N/A | AA22: =CONCATENATE(M22,U22) | AB22: =INDEX('справочная информация'!$B$68:$H$83,MATCH('Расчет грейда'!$AA22,'справочная информация'!$A$68:$A$83,0),MATCH('Расчет грейда'!$N22,'справочная информация'!$B$67:$H$67,0)) -> #N/A | AC22: =INDEX('справочная информация'!$D$130:$AD$145,MATCH('Расчет грейда'!$AW22,'справочная информация'!$C$130:$C$145,0),MATCH('Расчет грейда'!$AV22,'справочная информация'!$D$129:$AD$129,0)) -> #N/A | AD22: =CONCATENATE(P22,Q22) | AE22: =CONCATENATE(O22,V22) | AF22: =IFERROR(IF(AND(AD22="",AE22=""),"",INDEX('справочная информация'!$B$188:$Y$211,MATCH('Расчет грейда'!$AE22,'справочная информация'!$A$188:$A$211,0),MATCH('Расчет грейда'!$AD22,'справочная информация'!$B$187:$Y$187,0))),"НЕТ") | AG22: =VLOOKUP(J22,'справочная информация'!$D$267:$E$274,2,0) -> #N/A | AH22: =VLOOKUP(K22,'справочная информация'!$D$279:$E$283,2,0) -> #N/A | AI22: =VLOOKUP(L22,'справочная информация'!$D$288:$E$290,2,0) -> #N/A | AJ22: =AV22 | AK22: =VLOOKUP(M22,'справочная информация'!$D$294:$E$301,2,0) -> #N/A | AL22: =VLOOKUP(N22,'справочная информация'!$D$306:$E$310,2,0) -> #N/A | AM22: =CONCATENATE("(",AW22,")") -> () | AN22: =AX22 | AO22: =VLOOKUP(O22,'справочная информация'!$D$329:$E$336,2,0) -> #N/A | AP22: =VLOOKUP(P22,'справочная информация'!$D$342:$E$349,2,0) -> #N/A | AQ22: =VLOOKUP(Q22,'справочная информация'!$D$316:$E$325,2,0) -> #N/A | AR22: =AY22 | AS22: =AZ22 | AT22: =IF(AND(AX22="",AY22=""),"",IF(AY22>AX22,"A",IF(AX22=AY22,"L","P"))) | AU22: =ABS(MATCH($AX22,'справочная информация'!$A$354:$A$391,0)-MATCH($AY22,'справочная информация'!$A$354:$A$391,0)) -> #N/A | AV22: =IFERROR(INDEX('справочная информация'!$B$6:$R$29,MATCH('Расчет грейда'!$Y22,'справочная информация'!$A$6:$A$29,0),MATCH('Расчет грейда'!$X22,'справочная информация'!$B$5:$R$5,0)),"") | AW22: =IFERROR(INDEX('справочная информация'!$B$37:$H$52,MATCH('Расчет грейда'!$AA22,'справочная информация'!$A$37:$A$52,0),MATCH('Расчет грейда'!$N22,'справочная информация'!$B$36:$H$36,0)),"") | AX22: =IFERROR(INDEX('справочная информация'!$D$108:$AD$123,MATCH('Расчет грейда'!$AW22,'справочная информация'!$C$108:$C$123,0),MATCH('Расчет грейда'!$AV22,'справочная информация'!$D$107:$AD$107,0)),"") | AY22: =IFERROR(INDEX('справочная информация'!$B$158:$Y$181,MATCH('Расчет грейда'!$AE22,'справочная информация'!$A$158:$A$181,0),MATCH('Расчет грейда'!$AD22,'справочная информация'!$B$157:$Y$157,0)),"") | AZ22: =IFERROR(AV22+AX22+AY22,"") | BA22: =IFERROR(CONCATENATE(TEXT(AZ22/INDEX('справочная информация'!$D$223:$D$261,MATCH('Расчет грейда'!$AZ22,'справочная информация'!$C$223:$C$261,1)),"0%")," - процент относительно медианы 100%. ","MIN балл на грейде ",INDEX('справочная информация'!$C$223:$C$261,MATCH('Расчет грейда'!$AZ22,'справочная информация'!$C$223:$C$261,1)),", "," MAX балл на грейде ",INDEX('справочная информация'!$E$223:$E$261,MATCH('Расчет грейда'!$AZ22,'справочная информация'!$C$223:$C$261,1))),"") | BB22: =IFERROR(IF(AND(AX22="",AY22=""),"",IF(AY22>AX22,"Ответственный профиль (ACC)",IF(AY22=AX22,"Профиль равный (L)","Профиль решения вопросов (PS)"))),"") | BC22: =IFERROR(CONCATENATE(AT22,AU22),"") | BD22: =IFERROR(VLOOKUP(BC22,'справочная информация'!$B$416:$C$424,2,0),"Проверить данные, нетипичная должность") -> Проверить данные, нетипичная должность | BE22: =IFERROR(CONCATENATE(AG22,AH22,AI22," ",AJ22," ",AK22,AL22," ",AM22," ",AN22," ",AO22,AP22,AQ22," ",AR22," ",AS22," ",BC22),"") | BF22: =IFERROR(INDEX('справочная информация'!$F$223:$F$261,MATCH('Расчет грейда'!$AZ22,'справочная информация'!$C$223:$C$261,1)),"")
W23: =IF(IFERROR(BF23-6,"")<0,0,IFERROR(BF23-6,"")) | X23: =CONCATENATE(K23,L23) | Y23: =CONCATENATE(J23,T23) | Z23: =INDEX('справочная информация'!$U$6:$AK$29,MATCH('Расчет грейда'!$Y23,'справочная информация'!$T$6:$T$29,0),MATCH('Расчет грейда'!$X23,'справочная информация'!$U$5:$AK$5,0)) -> #N/A | AA23: =CONCATENATE(M23,U23) | AB23: =INDEX('справочная информация'!$B$68:$H$83,MATCH('Расчет грейда'!$AA23,'справочная информация'!$A$68:$A$83,0),MATCH('Расчет грейда'!$N23,'справочная информация'!$B$67:$H$67,0)) -> #N/A | AC23: =INDEX('справочная информация'!$D$130:$AD$145,MATCH('Расчет грейда'!$AW23,'справочная информация'!$C$130:$C$145,0),MATCH('Расчет грейда'!$AV23,'справочная информация'!$D$129:$AD$129,0)) -> #N/A | AD23: =CONCATENATE(P23,Q23) | AE23: =CONCATENATE(O23,V23) | AF23: =IFERROR(IF(AND(AD23="",AE23=""),"",INDEX('справочная информация'!$B$188:$Y$211,MATCH('Расчет грейда'!$AE23,'справочная информация'!$A$188:$A$211,0),MATCH('Расчет грейда'!$AD23,'справочная информация'!$B$187:$Y$187,0))),"НЕТ") | AG23: =VLOOKUP(J23,'справочная информация'!$D$267:$E$274,2,0) -> #N/A | AH23: =VLOOKUP(K23,'справочная информация'!$D$279:$E$283,2,0) -> #N/A | AI23: =VLOOKUP(L23,'справочная информация'!$D$288:$E$290,2,0) -> #N/A | AJ23: =AV23 | AK23: =VLOOKUP(M23,'справочная информация'!$D$294:$E$301,2,0) -> #N/A | AL23: =VLOOKUP(N23,'справочная информация'!$D$306:$E$310,2,0) -> #N/A | AM23: =CONCATENATE("(",AW23,")") -> () | AN23: =AX23 | AO23: =VLOOKUP(O23,'справочная информация'!$D$329:$E$336,2,0) -> #N/A | AP23: =VLOOKUP(P23,'справочная информация'!$D$342:$E$349,2,0) -> #N/A | AQ23: =VLOOKUP(Q23,'справочная информация'!$D$316:$E$325,2,0) -> #N/A | AR23: =AY23 | AS23: =AZ23 | AT23: =IF(AND(AX23="",AY23=""),"",IF(AY23>AX23,"A",IF(AX23=AY23,"L","P"))) | AU23: =ABS(MATCH($AX23,'справочная информация'!$A$354:$A$391,0)-MATCH($AY23,'справочная информация'!$A$354:$A$391,0)) -> #N/A | AV23: =IFERROR(INDEX('справочная информация'!$B$6:$R$29,MATCH('Расчет грейда'!$Y23,'справочная информация'!$A$6:$A$29,0),MATCH('Расчет грейда'!$X23,'справочная информация'!$B$5:$R$5,0)),"") | AW23: =IFERROR(INDEX('справочная информация'!$B$37:$H$52,MATCH('Расчет грейда'!$AA23,'справочная информация'!$A$37:$A$52,0),MATCH('Расчет грейда'!$N23,'справочная информация'!$B$36:$H$36,0)),"") | AX23: =IFERROR(INDEX('справочная информация'!$D$108:$AD$123,MATCH('Расчет грейда'!$AW23,'справочная информация'!$C$108:$C$123,0),MATCH('Расчет грейда'!$AV23,'справочная информация'!$D$107:$AD$107,0)),"") | AY23: =IFERROR(INDEX('справочная информация'!$B$158:$Y$181,MATCH('Расчет грейда'!$AE23,'справочная информация'!$A$158:$A$181,0),MATCH('Расчет грейда'!$AD23,'справочная информация'!$B$157:$Y$157,0)),"") | AZ23: =IFERROR(AV23+AX23+AY23,"") | BA23: =IFERROR(CONCATENATE(TEXT(AZ23/INDEX('справочная информация'!$D$223:$D$261,MATCH('Расчет грейда'!$AZ23,'справочная информация'!$C$223:$C$261,1)),"0%")," - процент относительно медианы 100%. ","MIN балл на грейде ",INDEX('справочная информация'!$C$223:$C$261,MATCH('Расчет грейда'!$AZ23,'справочная информация'!$C$223:$C$261,1)),", "," MAX балл на грейде ",INDEX('справочная информация'!$E$223:$E$261,MATCH('Расчет грейда'!$AZ23,'справочная информация'!$C$223:$C$261,1))),"") | BB23: =IFERROR(IF(AND(AX23="",AY23=""),"",IF(AY23>AX23,"Ответственный профиль (ACC)",IF(AY23=AX23,"Профиль равный (L)","Профиль решения вопросов (PS)"))),"") | BC23: =IFERROR(CONCATENATE(AT23,AU23),"") | BD23: =IFERROR(VLOOKUP(BC23,'справочная информация'!$B$416:$C$424,2,0),"Проверить данные, нетипичная должность") -> Проверить данные, нетипичная должность | BE23: =IFERROR(CONCATENATE(AG23,AH23,AI23," ",AJ23," ",AK23,AL23," ",AM23," ",AN23," ",AO23,AP23,AQ23," ",AR23," ",AS23," ",BC23),"") | BF23: =IFERROR(INDEX('справочная информация'!$F$223:$F$261,MATCH('Расчет грейда'!$AZ23,'справочная информация'!$C$223:$C$261,1)),"")
W24: =IF(IFERROR(BF24-6,"")<0,0,IFERROR(BF24-6,"")) | X24: =CONCATENATE(K24,L24) | Y24: =CONCATENATE(J24,T24) | Z24: =INDEX('справочная информация'!$U$6:$AK$29,MATCH('Расчет грейда'!$Y24,'справочная информация'!$T$6:$T$29,0),MATCH('Расчет грейда'!$X24,'справочная информация'!$U$5:$AK$5,0)) -> #N/A | AA24: =CONCATENATE(M24,U24) | AB24: =INDEX('справочная информация'!$B$68:$H$83,MATCH('Расчет грейда'!$AA24,'справочная информация'!$A$68:$A$83,0),MATCH('Расчет грейда'!$N24,'справочная информация'!$B$67:$H$67,0)) -> #N/A | AC24: =INDEX('справочная информация'!$D$130:$AD$145,MATCH('Расчет грейда'!$AW24,'справочная информация'!$C$130:$C$145,0),MATCH('Расчет грейда'!$AV24,'справочная информация'!$D$129:$AD$129,0)) -> #N/A | AD24: =CONCATENATE(P24,Q24) | AE24: =CONCATENATE(O24,V24) | AF24: =IFERROR(IF(AND(AD24="",AE24=""),"",INDEX('справочная информация'!$B$188:$Y$211,MATCH('Расчет грейда'!$AE24,'справочная информация'!$A$188:$A$211,0),MATCH('Расчет грейда'!$AD24,'справочная информация'!$B$187:$Y$187,0))),"НЕТ") | AG24: =VLOOKUP(J24,'справочная информация'!$D$267:$E$274,2,0) -> #N/A | AH24: =VLOOKUP(K24,'справочная информация'!$D$279:$E$283,2,0) -> #N/A | AI24: =VLOOKUP(L24,'справочная информация'!$D$288:$E$290,2,0) -> #N/A | AJ24: =AV24 | AK24: =VLOOKUP(M24,'справочная информация'!$D$294:$E$301,2,0) -> #N/A | AL24: =VLOOKUP(N24,'справочная информация'!$D$306:$E$310,2,0) -> #N/A | AM24: =CONCATENATE("(",AW24,")") -> () | AN24: =AX24 | AO24: =VLOOKUP(O24,'справочная информация'!$D$329:$E$336,2,0) -> #N/A | AP24: =VLOOKUP(P24,'справочная информация'!$D$342:$E$349,2,0) -> #N/A | AQ24: =VLOOKUP(Q24,'справочная информация'!$D$316:$E$325,2,0) -> #N/A | AR24: =AY24 | AS24: =AZ24 | AT24: =IF(AND(AX24="",AY24=""),"",IF(AY24>AX24,"A",IF(AX24=AY24,"L","P"))) | AU24: =ABS(MATCH($AX24,'справочная информация'!$A$354:$A$391,0)-MATCH($AY24,'справочная информация'!$A$354:$A$391,0)) -> #N/A | AV24: =IFERROR(INDEX('справочная информация'!$B$6:$R$29,MATCH('Расчет грейда'!$Y24,'справочная информация'!$A$6:$A$29,0),MATCH('Расчет грейда'!$X24,'справочная информация'!$B$5:$R$5,0)),"") | AW24: =IFERROR(INDEX('справочная информация'!$B$37:$H$52,MATCH('Расчет грейда'!$AA24,'справочная информация'!$A$37:$A$52,0),MATCH('Расчет грейда'!$N24,'справочная информация'!$B$36:$H$36,0)),"") | AX24: =IFERROR(INDEX('справочная информация'!$D$108:$AD$123,MATCH('Расчет грейда'!$AW24,'справочная информация'!$C$108:$C$123,0),MATCH('Расчет грейда'!$AV24,'справочная информация'!$D$107:$AD$107,0)),"") | AY24: =IFERROR(INDEX('справочная информация'!$B$158:$Y$181,MATCH('Расчет грейда'!$AE24,'справочная информация'!$A$158:$A$181,0),MATCH('Расчет грейда'!$AD24,'справочная информация'!$B$157:$Y$157,0)),"") | AZ24: =IFERROR(AV24+AX24+AY24,"") | BA24: =IFERROR(CONCATENATE(TEXT(AZ24/INDEX('справочная информация'!$D$223:$D$261,MATCH('Расчет грейда'!$AZ24,'справочная информация'!$C$223:$C$261,1)),"0%")," - процент относительно медианы 100%. ","MIN балл на грейде ",INDEX('справочная информация'!$C$223:$C$261,MATCH('Расчет грейда'!$AZ24,'справочная информация'!$C$223:$C$261,1)),", "," MAX балл на грейде ",INDEX('справочная информация'!$E$223:$E$261,MATCH('Расчет грейда'!$AZ24,'справочная информация'!$C$223:$C$261,1))),"") | BB24: =IFERROR(IF(AND(AX24="",AY24=""),"",IF(AY24>AX24,"Ответственный профиль (ACC)",IF(AY24=AX24,"Профиль равный (L)","Профиль решения вопросов (PS)"))),"") | BC24: =IFERROR(CONCATENATE(AT24,AU24),"") | BD24: =IFERROR(VLOOKUP(BC24,'справочная информация'!$B$416:$C$424,2,0),"Проверить данные, нетипичная должность") -> Проверить данные, нетипичная должность | BE24: =IFERROR(CONCATENATE(AG24,AH24,AI24," ",AJ24," ",AK24,AL24," ",AM24," ",AN24," ",AO24,AP24,AQ24," ",AR24," ",AS24," ",BC24),"") | BF24: =IFERROR(INDEX('справочная информация'!$F$223:$F$261,MATCH('Расчет грейда'!$AZ24,'справочная информация'!$C$223:$C$261,1)),"")
W25: =IF(IFERROR(BF25-6,"")<0,0,IFERROR(BF25-6,"")) | X25: =CONCATENATE(K25,L25) | Y25: =CONCATENATE(J25,T25) | Z25: =INDEX('справочная информация'!$U$6:$AK$29,MATCH('Расчет грейда'!$Y25,'справочная информация'!$T$6:$T$29,0),MATCH('Расчет грейда'!$X25,'справочная информация'!$U$5:$AK$5,0)) -> #N/A | AA25: =CONCATENATE(M25,U25) | AB25: =INDEX('справочная информация'!$B$68:$H$83,MATCH('Расчет грейда'!$AA25,'справочная информация'!$A$68:$A$83,0),MATCH('Расчет грейда'!$N25,'справочная информация'!$B$67:$H$67,0)) -> #N/A | AC25: =INDEX('справочная информация'!$D$130:$AD$145,MATCH('Расчет грейда'!$AW25,'справочная информация'!$C$130:$C$145,0),MATCH('Расчет грейда'!$AV25,'справочная информация'!$D$129:$AD$129,0)) -> #N/A | AD25: =CONCATENATE(P25,Q25) | AE25: =CONCATENATE(O25,V25) | AF25: =IFERROR(IF(AND(AD25="",AE25=""),"",INDEX('справочная информация'!$B$188:$Y$211,MATCH('Расчет грейда'!$AE25,'справочная информация'!$A$188:$A$211,0),MATCH('Расчет грейда'!$AD25,'справочная информация'!$B$187:$Y$187,0))),"НЕТ") | AG25: =VLOOKUP(J25,'справочная информация'!$D$267:$E$274,2,0) -> #N/A | AH25: =VLOOKUP(K25,'справочная информация'!$D$279:$E$283,2,0) -> #N/A | AI25: =VLOOKUP(L25,'справочная информация'!$D$288:$E$290,2,0) -> #N/A | AJ25: =AV25 | AK25: =VLOOKUP(M25,'справочная информация'!$D$294:$E$301,2,0) -> #N/A | AL25: =VLOOKUP(N25,'справочная информация'!$D$306:$E$310,2,0) -> #N/A | AM25: =CONCATENATE("(",AW25,")") -> () | AN25: =AX25 | AO25: =VLOOKUP(O25,'справочная информация'!$D$329:$E$336,2,0) -> #N/A | AP25: =VLOOKUP(P25,'справочная информация'!$D$342:$E$349,2,0) -> #N/A | AQ25: =VLOOKUP(Q25,'справочная информация'!$D$316:$E$325,2,0) -> #N/A | AR25: =AY25 | AS25: =AZ25 | AT25: =IF(AND(AX25="",AY25=""),"",IF(AY25>AX25,"A",IF(AX25=AY25,"L","P"))) | AU25: =ABS(MATCH($AX25,'справочная информация'!$A$354:$A$391,0)-MATCH($AY25,'справочная информация'!$A$354:$A$391,0)) -> #N/A | AV25: =IFERROR(INDEX('справочная информация'!$B$6:$R$29,MATCH('Расчет грейда'!$Y25,'справочная информация'!$A$6:$A$29,0),MATCH('Расчет грейда'!$X25,'справочная информация'!$B$5:$R$5,0)),"") | AW25: =IFERROR(INDEX('справочная информация'!$B$37:$H$52,MATCH('Расчет грейда'!$AA25,'справочная информация'!$A$37:$A$52,0),MATCH('Расчет грейда'!$N25,'справочная информация'!$B$36:$H$36,0)),"") | AX25: =IFERROR(INDEX('справочная информация'!$D$108:$AD$123,MATCH('Расчет грейда'!$AW25,'справочная информация'!$C$108:$C$123,0),MATCH('Расчет грейда'!$AV25,'справочная информация'!$D$107:$AD$107,0)),"") | AY25: =IFERROR(INDEX('справочная информация'!$B$158:$Y$181,MATCH('Расчет грейда'!$AE25,'справочная информация'!$A$158:$A$181,0),MATCH('Расчет грейда'!$AD25,'справочная информация'!$B$157:$Y$157,0)),"") | AZ25: =IFERROR(AV25+AX25+AY25,"") | BA25: =IFERROR(CONCATENATE(TEXT(AZ25/INDEX('справочная информация'!$D$223:$D$261,MATCH('Расчет грейда'!$AZ25,'справочная информация'!$C$223:$C$261,1)),"0%")," - процент относительно медианы 100%. ","MIN балл на грейде ",INDEX('справочная информация'!$C$223:$C$261,MATCH('Расчет грейда'!$AZ25,'справочная информация'!$C$223:$C$261,1)),", "," MAX балл на грейде ",INDEX('справочная информация'!$E$223:$E$261,MATCH('Расчет грейда'!$AZ25,'справочная информация'!$C$223:$C$261,1))),"") | BB25: =IFERROR(IF(AND(AX25="",AY25=""),"",IF(AY25>AX25,"Ответственный профиль (ACC)",IF(AY25=AX25,"Профиль равный (L)","Профиль решения вопросов (PS)"))),"") | BC25: =IFERROR(CONCATENATE(AT25,AU25),"") | BD25: =IFERROR(VLOOKUP(BC25,'справочная информация'!$B$416:$C$424,2,0),"Проверить данные, нетипичная должность") -> Проверить данные, нетипичная должность | BE25: =IFERROR(CONCATENATE(AG25,AH25,AI25," ",AJ25," ",AK25,AL25," ",AM25," ",AN25," ",AO25,AP25,AQ25," ",AR25," ",AS25," ",BC25),"") | BF25: =IFERROR(INDEX('справочная информация'!$F$223:$F$261,MATCH('Расчет грейда'!$AZ25,'справочная информация'!$C$223:$C$261,1)),"")
W26: =IF(IFERROR(BF26-6,"")<0,0,IFERROR(BF26-6,"")) | X26: =CONCATENATE(K26,L26) | Y26: =CONCATENATE(J26,T26) | Z26: =INDEX('справочная информация'!$U$6:$AK$29,MATCH('Расчет грейда'!$Y26,'справочная информация'!$T$6:$T$29,0),MATCH('Расчет грейда'!$X26,'справочная информация'!$U$5:$AK$5,0)) -> #N/A | AA26: =CONCATENATE(M26,U26) | AB26: =INDEX('справочная информация'!$B$68:$H$83,MATCH('Расчет грейда'!$AA26,'справочная информация'!$A$68:$A$83,0),MATCH('Расчет грейда'!$N26,'справочная информация'!$B$67:$H$67,0)) -> #N/A | AC26: =INDEX('справочная информация'!$D$130:$AD$145,MATCH('Расчет грейда'!$AW26,'справочная информация'!$C$130:$C$145,0),MATCH('Расчет грейда'!$AV26,'справочная информация'!$D$129:$AD$129,0)) -> #N/A | AD26: =CONCATENATE(P26,Q26) | AE26: =CONCATENATE(O26,V26) | AF26: =IFERROR(IF(AND(AD26="",AE26=""),"",INDEX('справочная информация'!$B$188:$Y$211,MATCH('Расчет грейда'!$AE26,'справочная информация'!$A$188:$A$211,0),MATCH('Расчет грейда'!$AD26,'справочная информация'!$B$187:$Y$187,0))),"НЕТ") | AG26: =VLOOKUP(J26,'справочная информация'!$D$267:$E$274,2,0) -> #N/A | AH26: =VLOOKUP(K26,'справочная информация'!$D$279:$E$283,2,0) -> #N/A | AI26: =VLOOKUP(L26,'справочная информация'!$D$288:$E$290,2,0) -> #N/A | AJ26: =AV26 | AK26: =VLOOKUP(M26,'справочная информация'!$D$294:$E$301,2,0) -> #N/A | AL26: =VLOOKUP(N26,'справочная информация'!$D$306:$E$310,2,0) -> #N/A | AM26: =CONCATENATE("(",AW26,")") -> () | AN26: =AX26 | AO26: =VLOOKUP(O26,'справочная информация'!$D$329:$E$336,2,0) -> #N/A | AP26: =VLOOKUP(P26,'справочная информация'!$D$342:$E$349,2,0) -> #N/A | AQ26: =VLOOKUP(Q26,'справочная информация'!$D$316:$E$325,2,0) -> #N/A | AR26: =AY26 | AS26: =AZ26 | AT26: =IF(AND(AX26="",AY26=""),"",IF(AY26>AX26,"A",IF(AX26=AY26,"L","P"))) | AU26: =ABS(MATCH($AX26,'справочная информация'!$A$354:$A$391,0)-MATCH($AY26,'справочная информация'!$A$354:$A$391,0)) -> #N/A | AV26: =IFERROR(INDEX('справочная информация'!$B$6:$R$29,MATCH('Расчет грейда'!$Y26,'справочная информация'!$A$6:$A$29,0),MATCH('Расчет грейда'!$X26,'справочная информация'!$B$5:$R$5,0)),"") | AW26: =IFERROR(INDEX('справочная информация'!$B$37:$H$52,MATCH('Расчет грейда'!$AA26,'справочная информация'!$A$37:$A$52,0),MATCH('Расчет грейда'!$N26,'справочная информация'!$B$36:$H$36,0)),"") | AX26: =IFERROR(INDEX('справочная информация'!$D$108:$AD$123,MATCH('Расчет грейда'!$AW26,'справочная информация'!$C$108:$C$123,0),MATCH('Расчет грейда'!$AV26,'справочная информация'!$D$107:$AD$107,0)),"") | AY26: =IFERROR(INDEX('справочная информация'!$B$158:$Y$181,MATCH('Расчет грейда'!$AE26,'справочная информация'!$A$158:$A$181,0),MATCH('Расчет грейда'!$AD26,'справочная информация'!$B$157:$Y$157,0)),"") | AZ26: =IFERROR(AV26+AX26+AY26,"") | BA26: =IFERROR(CONCATENATE(TEXT(AZ26/INDEX('справочная информация'!$D$223:$D$261,MATCH('Расчет грейда'!$AZ26,'справочная информация'!$C$223:$C$261,1)),"0%")," - процент относительно медианы 100%. ","MIN балл на грейде ",INDEX('справочная информация'!$C$223:$C$261,MATCH('Расчет грейда'!$AZ26,'справочная информация'!$C$223:$C$261,1)),", "," MAX балл на грейде ",INDEX('справочная информация'!$E$223:$E$261,MATCH('Расчет грейда'!$AZ26,'справочная информация'!$C$223:$C$261,1))),"") | BB26: =IFERROR(IF(AND(AX26="",AY26=""),"",IF(AY26>AX26,"Ответственный профиль (ACC)",IF(AY26=AX26,"Профиль равный (L)","Профиль решения вопросов (PS)"))),"") | BC26: =IFERROR(CONCATENATE(AT26,AU26),"") | BD26: =IFERROR(VLOOKUP(BC26,'справочная информация'!$B$416:$C$424,2,0),"Проверить данные, нетипичная должность") -> Проверить данные, нетипичная должность | BE26: =IFERROR(CONCATENATE(AG26,AH26,AI26," ",AJ26," ",AK26,AL26," ",AM26," ",AN26," ",AO26,AP26,AQ26," ",AR26," ",AS26," ",BC26),"") | BF26: =IFERROR(INDEX('справочная информация'!$F$223:$F$261,MATCH('Расчет грейда'!$AZ26,'справочная информация'!$C$223:$C$261,1)),"")
W27: =IF(IFERROR(BF27-6,"")<0,0,IFERROR(BF27-6,"")) | X27: =CONCATENATE(K27,L27) | Y27: =CONCATENATE(J27,T27) | Z27: =INDEX('справочная информация'!$U$6:$AK$29,MATCH('Расчет грейда'!$Y27,'справочная информация'!$T$6:$T$29,0),MATCH('Расчет грейда'!$X27,'справочная информация'!$U$5:$AK$5,0)) -> #N/A | AA27: =CONCATENATE(M27,U27) | AB27: =INDEX('справочная информация'!$B$68:$H$83,MATCH('Расчет грейда'!$AA27,'справочная информация'!$A$68:$A$83,0),MATCH('Расчет грейда'!$N27,'справочная информация'!$B$67:$H$67,0)) -> #N/A | AC27: =INDEX('справочная информация'!$D$130:$AD$145,MATCH('Расчет грейда'!$AW27,'справочная информация'!$C$130:$C$145,0),MATCH('Расчет грейда'!$AV27,'справочная информация'!$D$129:$AD$129,0)) -> #N/A | AD27: =CONCATENATE(P27,Q27) | AE27: =CONCATENATE(O27,V27) | AF27: =IFERROR(IF(AND(AD27="",AE27=""),"",INDEX('справочная информация'!$B$188:$Y$211,MATCH('Расчет грейда'!$AE27,'справочная информация'!$A$188:$A$211,0),MATCH('Расчет грейда'!$AD27,'справочная информация'!$B$187:$Y$187,0))),"НЕТ") | AG27: =VLOOKUP(J27,'справочная информация'!$D$267:$E$274,2,0) -> #N/A | AH27: =VLOOKUP(K27,'справочная информация'!$D$279:$E$283,2,0) -> #N/A | AI27: =VLOOKUP(L27,'справочная информация'!$D$288:$E$290,2,0) -> #N/A | AJ27: =AV27 | AK27: =VLOOKUP(M27,'справочная информация'!$D$294:$E$301,2,0) -> #N/A | AL27: =VLOOKUP(N27,'справочная информация'!$D$306:$E$310,2,0) -> #N/A | AM27: =CONCATENATE("(",AW27,")") -> () | AN27: =AX27 | AO27: =VLOOKUP(O27,'справочная информация'!$D$329:$E$336,2,0) -> #N/A | AP27: =VLOOKUP(P27,'справочная информация'!$D$342:$E$349,2,0) -> #N/A | AQ27: =VLOOKUP(Q27,'справочная информация'!$D$316:$E$325,2,0) -> #N/A | AR27: =AY27 | AS27: =AZ27 | AT27: =IF(AND(AX27="",AY27=""),"",IF(AY27>AX27,"A",IF(AX27=AY27,"L","P"))) | AU27: =ABS(MATCH($AX27,'справочная информация'!$A$354:$A$391,0)-MATCH($AY27,'справочная информация'!$A$354:$A$391,0)) -> #N/A | AV27: =IFERROR(INDEX('справочная информация'!$B$6:$R$29,MATCH('Расчет грейда'!$Y27,'справочная информация'!$A$6:$A$29,0),MATCH('Расчет грейда'!$X27,'справочная информация'!$B$5:$R$5,0)),"") | AW27: =IFERROR(INDEX('справочная информация'!$B$37:$H$52,MATCH('Расчет грейда'!$AA27,'справочная информация'!$A$37:$A$52,0),MATCH('Расчет грейда'!$N27,'справочная информация'!$B$36:$H$36,0)),"") | AX27: =IFERROR(INDEX('справочная информация'!$D$108:$AD$123,MATCH('Расчет грейда'!$AW27,'справочная информация'!$C$108:$C$123,0),MATCH('Расчет грейда'!$AV27,'справочная информация'!$D$107:$AD$107,0)),"") | AY27: =IFERROR(INDEX('справочная информация'!$B$158:$Y$181,MATCH('Расчет грейда'!$AE27,'справочная информация'!$A$158:$A$181,0),MATCH('Расчет грейда'!$AD27,'справочная информация'!$B$157:$Y$157,0)),"") | AZ27: =IFERROR(AV27+AX27+AY27,"") | BA27: =IFERROR(CONCATENATE(TEXT(AZ27/INDEX('справочная информация'!$D$223:$D$261,MATCH('Расчет грейда'!$AZ27,'справочная информация'!$C$223:$C$261,1)),"0%")," - процент относительно медианы 100%. ","MIN балл на грейде ",INDEX('справочная информация'!$C$223:$C$261,MATCH('Расчет грейда'!$AZ27,'справочная информация'!$C$223:$C$261,1)),", "," MAX балл на грейде ",INDEX('справочная информация'!$E$223:$E$261,MATCH('Расчет грейда'!$AZ27,'справочная информация'!$C$223:$C$261,1))),"") | BB27: =IFERROR(IF(AND(AX27="",AY27=""),"",IF(AY27>AX27,"Ответственный профиль (ACC)",IF(AY27=AX27,"Профиль равный (L)","Профиль решения вопросов (PS)"))),"") | BC27: =IFERROR(CONCATENATE(AT27,AU27),"") | BD27: =IFERROR(VLOOKUP(BC27,'справочная информация'!$B$416:$C$424,2,0),"Проверить данные, нетипичная должность") -> Проверить данные, нетипичная должность | BE27: =IFERROR(CONCATENATE(AG27,AH27,AI27," ",AJ27," ",AK27,AL27," ",AM27," ",AN27," ",AO27,AP27,AQ27," ",AR27," ",AS27," ",BC27),"") | BF27: =IFERROR(INDEX('справочная информация'!$F$223:$F$261,MATCH('Расчет грейда'!$AZ27,'справочная информация'!$C$223:$C$261,1)),"")
W28: =IF(IFERROR(BF28-6,"")<0,0,IFERROR(BF28-6,"")) | X28: =CONCATENATE(K28,L28) | Y28: =CONCATENATE(J28,T28) | Z28: =INDEX('справочная информация'!$U$6:$AK$29,MATCH('Расчет грейда'!$Y28,'справочная информация'!$T$6:$T$29,0),MATCH('Расчет грейда'!$X28,'справочная информация'!$U$5:$AK$5,0)) -> #N/A | AA28: =CONCATENATE(M28,U28) | AB28: =INDEX('справочная информация'!$B$68:$H$83,MATCH('Расчет грейда'!$AA28,'справочная информация'!$A$68:$A$83,0),MATCH('Расчет грейда'!$N28,'справочная информация'!$B$67:$H$67,0)) -> #N/A | AC28: =INDEX('справочная информация'!$D$130:$AD$145,MATCH('Расчет грейда'!$AW28,'справочная информация'!$C$130:$C$145,0),MATCH('Расчет грейда'!$AV28,'справочная информация'!$D$129:$AD$129,0)) -> #N/A | AD28: =CONCATENATE(P28,Q28) | AE28: =CONCATENATE(O28,V28) | AF28: =IFERROR(IF(AND(AD28="",AE28=""),"",INDEX('справочная информация'!$B$188:$Y$211,MATCH('Расчет грейда'!$AE28,'справочная информация'!$A$188:$A$211,0),MATCH('Расчет грейда'!$AD28,'справочная информация'!$B$187:$Y$187,0))),"НЕТ") | AG28: =VLOOKUP(J28,'справочная информация'!$D$267:$E$274,2,0) -> #N/A | AH28: =VLOOKUP(K28,'справочная информация'!$D$279:$E$283,2,0) -> #N/A | AI28: =VLOOKUP(L28,'справочная информация'!$D$288:$E$290,2,0) -> #N/A | AJ28: =AV28 | AK28: =VLOOKUP(M28,'справочная информация'!$D$294:$E$301,2,0) -> #N/A | AL28: =VLOOKUP(N28,'справочная информация'!$D$306:$E$310,2,0) -> #N/A | AM28: =CONCATENATE("(",AW28,")") -> () | AN28: =AX28 | AO28: =VLOOKUP(O28,'справочная информация'!$D$329:$E$336,2,0) -> #N/A | AP28: =VLOOKUP(P28,'справочная информация'!$D$342:$E$349,2,0) -> #N/A | AQ28: =VLOOKUP(Q28,'справочная информация'!$D$316:$E$325,2,0) -> #N/A | AR28: =AY28 | AS28: =AZ28 | AT28: =IF(AND(AX28="",AY28=""),"",IF(AY28>AX28,"A",IF(AX28=AY28,"L","P"))) | AU28: =ABS(MATCH($AX28,'справочная информация'!$A$354:$A$391,0)-MATCH($AY28,'справочная информация'!$A$354:$A$391,0)) -> #N/A | AV28: =IFERROR(INDEX('справочная информация'!$B$6:$R$29,MATCH('Расчет грейда'!$Y28,'справочная информация'!$A$6:$A$29,0),MATCH('Расчет грейда'!$X28,'справочная информация'!$B$5:$R$5,0)),"") | AW28: =IFERROR(INDEX('справочная информация'!$B$37:$H$52,MATCH('Расчет грейда'!$AA28,'справочная информация'!$A$37:$A$52,0),MATCH('Расчет грейда'!$N28,'справочная информация'!$B$36:$H$36,0)),"") | AX28: =IFERROR(INDEX('справочная информация'!$D$108:$AD$123,MATCH('Расчет грейда'!$AW28,'справочная информация'!$C$108:$C$123,0),MATCH('Расчет грейда'!$AV28,'справочная информация'!$D$107:$AD$107,0)),"") | AY28: =IFERROR(INDEX('справочная информация'!$B$158:$Y$181,MATCH('Расчет грейда'!$AE28,'справочная информация'!$A$158:$A$181,0),MATCH('Расчет грейда'!$AD28,'справочная информация'!$B$157:$Y$157,0)),"") | AZ28: =IFERROR(AV28+AX28+AY28,"") | BA28: =IFERROR(CONCATENATE(TEXT(AZ28/INDEX('справочная информация'!$D$223:$D$261,MATCH('Расчет грейда'!$AZ28,'справочная информация'!$C$223:$C$261,1)),"0%")," - процент относительно медианы 100%. ","MIN балл на грейде ",INDEX('справочная информация'!$C$223:$C$261,MATCH('Расчет грейда'!$AZ28,'справочная информация'!$C$223:$C$261,1)),", "," MAX балл на грейде ",INDEX('справочная информация'!$E$223:$E$261,MATCH('Расчет грейда'!$AZ28,'справочная информация'!$C$223:$C$261,1))),"") | BB28: =IFERROR(IF(AND(AX28="",AY28=""),"",IF(AY28>AX28,"Ответственный профиль (ACC)",IF(AY28=AX28,"Профиль равный (L)","Профиль решения вопросов (PS)"))),"") | BC28: =IFERROR(CONCATENATE(AT28,AU28),"") | BD28: =IFERROR(VLOOKUP(BC28,'справочная информация'!$B$416:$C$424,2,0),"Проверить данные, нетипичная должность") -> Проверить данные, нетипичная должность | BE28: =IFERROR(CONCATENATE(AG28,AH28,AI28," ",AJ28," ",AK28,AL28," ",AM28," ",AN28," ",AO28,AP28,AQ28," ",AR28," ",AS28," ",BC28),"") | BF28: =IFERROR(INDEX('справочная информация'!$F$223:$F$261,MATCH('Расчет грейда'!$AZ28,'справочная информация'!$C$223:$C$261,1)),"")
W29: =IF(IFERROR(BF29-6,"")<0,0,IFERROR(BF29-6,"")) | X29: =CONCATENATE(K29,L29) | Y29: =CONCATENATE(J29,T29) | Z29: =INDEX('справочная информация'!$U$6:$AK$29,MATCH('Расчет грейда'!$Y29,'справочная информация'!$T$6:$T$29,0),MATCH('Расчет грейда'!$X29,'справочная информация'!$U$5:$AK$5,0)) -> #N/A | AA29: =CONCATENATE(M29,U29) | AB29: =INDEX('справочная информация'!$B$68:$H$83,MATCH('Расчет грейда'!$AA29,'справочная информация'!$A$68:$A$83,0),MATCH('Расчет грейда'!$N29,'справочная информация'!$B$67:$H$67,0)) -> #N/A | AC29: =INDEX('справочная информация'!$D$130:$AD$145,MATCH('Расчет грейда'!$AW29,'справочная информация'!$C$130:$C$145,0),MATCH('Расчет грейда'!$AV29,'справочная информация'!$D$129:$AD$129,0)) -> #N/A | AD29: =CONCATENATE(P29,Q29) | AE29: =CONCATENATE(O29,V29) | AF29: =IFERROR(IF(AND(AD29="",AE29=""),"",INDEX('справочная информация'!$B$188:$Y$211,MATCH('Расчет грейда'!$AE29,'справочная информация'!$A$188:$A$211,0),MATCH('Расчет грейда'!$AD29,'справочная информация'!$B$187:$Y$187,0))),"НЕТ") | AG29: =VLOOKUP(J29,'справочная информация'!$D$267:$E$274,2,0) -> #N/A | AH29: =VLOOKUP(K29,'справочная информация'!$D$279:$E$283,2,0) -> #N/A | AI29: =VLOOKUP(L29,'справочная информация'!$D$288:$E$290,2,0) -> #N/A | AJ29: =AV29 | AK29: =VLOOKUP(M29,'справочная информация'!$D$294:$E$301,2,0) -> #N/A | AL29: =VLOOKUP(N29,'справочная информация'!$D$306:$E$310,2,0) -> #N/A | AM29: =CONCATENATE("(",AW29,")") -> () | AN29: =AX29 | AO29: =VLOOKUP(O29,'справочная информация'!$D$329:$E$336,2,0) -> #N/A | AP29: =VLOOKUP(P29,'справочная информация'!$D$342:$E$349,2,0) -> #N/A | AQ29: =VLOOKUP(Q29,'справочная информация'!$D$316:$E$325,2,0) -> #N/A | AR29: =AY29 | AS29: =AZ29 | AT29: =IF(AND(AX29="",AY29=""),"",IF(AY29>AX29,"A",IF(AX29=AY29,"L","P"))) | AU29: =ABS(MATCH($AX29,'справочная информация'!$A$354:$A$391,0)-MATCH($AY29,'справочная информация'!$A$354:$A$391,0)) -> #N/A | AV29: =IFERROR(INDEX('справочная информация'!$B$6:$R$29,MATCH('Расчет грейда'!$Y29,'справочная информация'!$A$6:$A$29,0),MATCH('Расчет грейда'!$X29,'справочная информация'!$B$5:$R$5,0)),"") | AW29: =IFERROR(INDEX('справочная информация'!$B$37:$H$52,MATCH('Расчет грейда'!$AA29,'справочная информация'!$A$37:$A$52,0),MATCH('Расчет грейда'!$N29,'справочная информация'!$B$36:$H$36,0)),"") | AX29: =IFERROR(INDEX('справочная информация'!$D$108:$AD$123,MATCH('Расчет грейда'!$AW29,'справочная информация'!$C$108:$C$123,0),MATCH('Расчет грейда'!$AV29,'справочная информация'!$D$107:$AD$107,0)),"") | AY29: =IFERROR(INDEX('справочная информация'!$B$158:$Y$181,MATCH('Расчет грейда'!$AE29,'справочная информация'!$A$158:$A$181,0),MATCH('Расчет грейда'!$AD29,'справочная информация'!$B$157:$Y$157,0)),"") | AZ29: =IFERROR(AV29+AX29+AY29,"") | BA29: =IFERROR(CONCATENATE(TEXT(AZ29/INDEX('справочная информация'!$D$223:$D$261,MATCH('Расчет грейда'!$AZ29,'справочная информация'!$C$223:$C$261,1)),"0%")," - процент относительно медианы 100%. ","MIN балл на грейде ",INDEX('справочная информация'!$C$223:$C$261,MATCH('Расчет грейда'!$AZ29,'справочная информация'!$C$223:$C$261,1)),", "," MAX балл на грейде ",INDEX('справочная информация'!$E$223:$E$261,MATCH('Расчет грейда'!$AZ29,'справочная информация'!$C$223:$C$261,1))),"") | BB29: =IFERROR(IF(AND(AX29="",AY29=""),"",IF(AY29>AX29,"Ответственный профиль (ACC)",IF(AY29=AX29,"Профиль равный (L)","Профиль решения вопросов (PS)"))),"") | BC29: =IFERROR(CONCATENATE(AT29,AU29),"") | BD29: =IFERROR(VLOOKUP(BC29,'справочная информация'!$B$416:$C$424,2,0),"Проверить данные, нетипичная должность") -> Проверить данные, нетипичная должность | BE29: =IFERROR(CONCATENATE(AG29,AH29,AI29," ",AJ29," ",AK29,AL29," ",AM29," ",AN29," ",AO29,AP29,AQ29," ",AR29," ",AS29," ",BC29),"") | BF29: =IFERROR(INDEX('справочная информация'!$F$223:$F$261,MATCH('Расчет грейда'!$AZ29,'справочная информация'!$C$223:$C$261,1)),"")
W30: =IF(IFERROR(BF30-6,"")<0,0,IFERROR(BF30-6,"")) | X30: =CONCATENATE(K30,L30) | Y30: =CONCATENATE(J30,T30) | Z30: =INDEX('справочная информация'!$U$6:$AK$29,MATCH('Расчет грейда'!$Y30,'справочная информация'!$T$6:$T$29,0),MATCH('Расчет грейда'!$X30,'справочная информация'!$U$5:$AK$5,0)) -> #N/A | AA30: =CONCATENATE(M30,U30) | AB30: =INDEX('справочная информация'!$B$68:$H$83,MATCH('Расчет грейда'!$AA30,'справочная информация'!$A$68:$A$83,0),MATCH('Расчет грейда'!$N30,'справочная информация'!$B$67:$H$67,0)) -> #N/A | AC30: =INDEX('справочная информация'!$D$130:$AD$145,MATCH('Расчет грейда'!$AW30,'справочная информация'!$C$130:$C$145,0),MATCH('Расчет грейда'!$AV30,'справочная информация'!$D$129:$AD$129,0)) -> #N/A | AD30: =CONCATENATE(P30,Q30) | AE30: =CONCATENATE(O30,V30) | AF30: =IFERROR(IF(AND(AD30="",AE30=""),"",INDEX('справочная информация'!$B$188:$Y$211,MATCH('Расчет грейда'!$AE30,'справочная информация'!$A$188:$A$211,0),MATCH('Расчет грейда'!$AD30,'справочная информация'!$B$187:$Y$187,0))),"НЕТ") | AG30: =VLOOKUP(J30,'справочная информация'!$D$267:$E$274,2,0) -> #N/A | AH30: =VLOOKUP(K30,'справочная информация'!$D$279:$E$283,2,0) -> #N/A | AI30: =VLOOKUP(L30,'справочная информация'!$D$288:$E$290,2,0) -> #N/A | AJ30: =AV30 | AK30: =VLOOKUP(M30,'справочная информация'!$D$294:$E$301,2,0) -> #N/A | AL30: =VLOOKUP(N30,'справочная информация'!$D$306:$E$310,2,0) -> #N/A | AM30: =CONCATENATE("(",AW30,")") -> () | AN30: =AX30 | AO30: =VLOOKUP(O30,'справочная информация'!$D$329:$E$336,2,0) -> #N/A | AP30: =VLOOKUP(P30,'справочная информация'!$D$342:$E$349,2,0) -> #N/A | AQ30: =VLOOKUP(Q30,'справочная информация'!$D$316:$E$325,2,0) -> #N/A | AR30: =AY30 | AS30: =AZ30 | AT30: =IF(AND(AX30="",AY30=""),"",IF(AY30>AX30,"A",IF(AX30=AY30,"L","P"))) | AU30: =ABS(MATCH($AX30,'справочная информация'!$A$354:$A$391,0)-MATCH($AY30,'справочная информация'!$A$354:$A$391,0)) -> #N/A | AV30: =IFERROR(INDEX('справочная информация'!$B$6:$R$29,MATCH('Расчет грейда'!$Y30,'справочная информация'!$A$6:$A$29,0),MATCH('Расчет грейда'!$X30,'справочная информация'!$B$5:$R$5,0)),"") | AW30: =IFERROR(INDEX('справочная информация'!$B$37:$H$52,MATCH('Расчет грейда'!$AA30,'справочная информация'!$A$37:$A$52,0),MATCH('Расчет грейда'!$N30,'справочная информация'!$B$36:$H$36,0)),"") | AX30: =IFERROR(INDEX('справочная информация'!$D$108:$AD$123,MATCH('Расчет грейда'!$AW30,'справочная информация'!$C$108:$C$123,0),MATCH('Расчет грейда'!$AV30,'справочная информация'!$D$107:$AD$107,0)),"") | AY30: =IFERROR(INDEX('справочная информация'!$B$158:$Y$181,MATCH('Расчет грейда'!$AE30,'справочная информация'!$A$158:$A$181,0),MATCH('Расчет грейда'!$AD30,'справочная информация'!$B$157:$Y$157,0)),"") | AZ30: =IFERROR(AV30+AX30+AY30,"") | BA30: =IFERROR(CONCATENATE(TEXT(AZ30/INDEX('справочная информация'!$D$223:$D$261,MATCH('Расчет грейда'!$AZ30,'справочная информация'!$C$223:$C$261,1)),"0%")," - процент относительно медианы 100%. ","MIN балл на грейде ",INDEX('справочная информация'!$C$223:$C$261,MATCH('Расчет грейда'!$AZ30,'справочная информация'!$C$223:$C$261,1)),", "," MAX балл на грейде ",INDEX('справочная информация'!$E$223:$E$261,MATCH('Расчет грейда'!$AZ30,'справочная информация'!$C$223:$C$261,1))),"") | BB30: =IFERROR(IF(AND(AX30="",AY30=""),"",IF(AY30>AX30,"Ответственный профиль (ACC)",IF(AY30=AX30,"Профиль равный (L)","Профиль решения вопросов (PS)"))),"") | BC30: =IFERROR(CONCATENATE(AT30,AU30),"") | BD30: =IFERROR(VLOOKUP(BC30,'справочная информация'!$B$416:$C$424,2,0),"Проверить данные, нетипичная должность") -> Проверить данные, нетипичная должность | BE30: =IFERROR(CONCATENATE(AG30,AH30,AI30," ",AJ30," ",AK30,AL30," ",AM30," ",AN30," ",AO30,AP30,AQ30," ",AR30," ",AS30," ",BC30),"") | BF30: =IFERROR(INDEX('справочная информация'!$F$223:$F$261,MATCH('Расчет грейда'!$AZ30,'справочная информация'!$C$223:$C$261,1)),"")
... W185: =IF(IFERROR(BF185-6,"")<0,0,IFERROR(BF185-6,"")) | X185: =CONCATENATE(K185,L185) | Y185: =CONCATENATE(J185,T185) | Z185: =INDEX('справочная информация'!$U$6:$AK$29,MATCH('Расчет грейда'!$Y185,'справочная информация'!$T$6:$T$29,0),MATCH('Расчет грейда'!$X185,'справочная информация'!$U$5:$AK$5,0)) -> #N/A | AA185: =CONCATENATE(M185,U185) | AB185: =INDEX('справочная информация'!$B$68:$H$83,MATCH('Расчет грейда'!$AA185,'справочная информация'!$A$68:$A$83,0),MATCH('Расчет грейда'!$N185,'справочная информация'!$B$67:$H$67,0)) -> #N/A | AC185: =INDEX('справочная информация'!$D$130:$AD$145,MATCH('Расчет грейда'!$AW185,'справочная информация'!$C$130:$C$145,0),MATCH('Расчет грейда'!$AV185,'справочная информация'!$D$129:$AD$129,0)) -> #N/A | AD185: =CONCATENATE(P185,Q185) | AE185: =CONCATENATE(O185,V185) | AF185: =IFERROR(IF(AND(AD185="",AE185=""),"",INDEX('справочная информация'!$B$188:$Y$211,MATCH('Расчет грейда'!$AE185,'справочная информация'!$A$188:$A$211,0),MATCH('Расчет грейда'!$AD185,'справочная информация'!$B$187:$Y$187,0))),"НЕТ") | AG185: =VLOOKUP(J185,'справочная информация'!$D$267:$E$274,2,0) -> #N/A | AH185: =VLOOKUP(K185,'справочная информация'!$D$279:$E$283,2,0) -> #N/A | AI185: =VLOOKUP(L185,'справочная информация'!$D$288:$E$290,2,0) -> #N/A | AJ185: =AV185 | AK185: =VLOOKUP(M185,'справочная информация'!$D$294:$E$301,2,0) -> #N/A | AL185: =VLOOKUP(N185,'справочная информация'!$D$306:$E$310,2,0) -> #N/A | AM185: =CONCATENATE("(",AW185,")") -> () | AN185: =AX185 | AO185: =VLOOKUP(O185,'справочная информация'!$D$329:$E$336,2,0) -> #N/A | AP185: =VLOOKUP(P185,'справочная информация'!$D$342:$E$349,2,0) -> #N/A | AQ185: =VLOOKUP(Q185,'справочная информация'!$D$316:$E$325,2,0) -> #N/A | AR185: =AY185 | AS185: =AZ185 | AT185: =IF(AND(AX185="",AY185=""),"",IF(AY185>AX185,"A",IF(AX185=AY185,"L","P"))) | AU185: =ABS(MATCH($AX185,'справочная информация'!$A$354:$A$391,0)-MATCH($AY185,'справочная информация'!$A$354:$A$391,0)) -> #N/A | AV185: =IFERROR(INDEX('справочная информация'!$B$6:$R$29,MATCH('Расчет грейда'!$Y185,'справочная информация'!$A$6:$A$29,0),MATCH('Расчет грейда'!$X185,'справочная информация'!$B$5:$R$5,0)),"") | AW185: =IFERROR(INDEX('справочная информация'!$B$37:$H$52,MATCH('Расчет грейда'!$AA185,'справочная информация'!$A$37:$A$52,0),MATCH('Расчет грейда'!$N185,'справочная информация'!$B$36:$H$36,0)),"") | AX185: =IFERROR(INDEX('справочная информация'!$D$108:$AD$123,MATCH('Расчет грейда'!$AW185,'справочная информация'!$C$108:$C$123,0),MATCH('Расчет грейда'!$AV185,'справочная информация'!$D$107:$AD$107,0)),"") | AY185: =IFERROR(INDEX('справочная информация'!$B$158:$Y$181,MATCH('Расчет грейда'!$AE185,'справочная информация'!$A$158:$A$181,0),MATCH('Расчет грейда'!$AD185,'справочная информация'!$B$157:$Y$157,0)),"") | AZ185: =IFERROR(AV185+AX185+AY185,"") | BA185: =IFERROR(CONCATENATE(TEXT(AZ185/INDEX('справочная информация'!$D$223:$D$261,MATCH('Расчет грейда'!$AZ185,'справочная информация'!$C$223:$C$261,1)),"0%")," - процент относительно медианы 100%. ","MIN балл на грейде ",INDEX('справочная информация'!$C$223:$C$261,MATCH('Расчет грейда'!$AZ185,'справочная информация'!$C$223:$C$261,1)),", "," MAX балл на грейде ",INDEX('справочная информация'!$E$223:$E$261,MATCH('Расчет грейда'!$AZ185,'справочная информация'!$C$223:$C$261,1))),"") | BB185: =IFERROR(IF(AND(AX185="",AY185=""),"",IF(AY185>AX185,"Ответственный профиль (ACC)",IF(AY185=AX185,"Профиль равный (L)","Профиль решения вопросов (PS)"))),"") | BC185: =IFERROR(CONCATENATE(AT185,AU185),"") | BD185: =IFERROR(VLOOKUP(BC185,'справочная информация'!$B$416:$C$424,2,0),"Проверить данные, нетипичная должность") -> Проверить данные, нетипичная должность | BE185: =IFERROR(CONCATENATE(AG185,AH185,AI185," ",AJ185," ",AK185,AL185," ",AM185," ",AN185," ",AO185,AP185,AQ185," ",AR185," ",AS185," ",BC185),"") | BF185: =IFERROR(INDEX('справочная информация'!$F$223:$F$261,MATCH('Расчет грейда'!$AZ185,'справочная информация'!$C$223:$C$261,1)),"")

Sheet ТРС общая
D2: 1 | E2: 2 | F2: 3 | G2: 4 | H2: 5 | I2: 6 | J2: 7 | K2: 8 | L2: 9 | M2: 10 | N2: 11 | O2: 12 | P2: 13 | Q2: 14 | R2: 15 | S2: 16 | T2: 17 | U2: 18 | V2: 19 | W2: 20 | X2: 21 | Y2: 22 | Z2: 23 | AA2: 24 | AB2: 25 | AC2: 26 | AD2: 27 | AE2: 28 | AF2: 29 | AG2: 30 | AH2: 31 | AI2: 32 | AJ2: 33
B6: AS IS
B7: Грейд | C7: Кол-во ролей
B8: 20 | C8: =COUNTIF('Расчет грейда'!$W:$W,'ТРС общая'!$B8) -> 0 | D8: {=IFERROR(INDEX(#REF!,SMALL(IF('ТРС общая'!$B8=#REF!,ROW(#REF!)-18,""),ROW()-(ROW()-D$2))),"")} | E8: {=IFERROR(INDEX(#REF!,SMALL(IF('ТРС общая'!$B8=#REF!,ROW(#REF!)-18,""),ROW()-(ROW()-E$2))),"")} | F8: {=IFERROR(INDEX(#REF!,SMALL(IF('ТРС общая'!$B8=#REF!,ROW(#REF!)-18,""),ROW()-(ROW()-F$2))),"")} | G8: {=IFERROR(INDEX(#REF!,SMALL(IF('ТРС общая'!$B8=#REF!,ROW(#REF!)-18,""),ROW()-(ROW()-G$2))),"")} | H8: {=IFERROR(INDEX(#REF!,SMALL(IF('ТРС общая'!$B8=#REF!,ROW(#REF!)-18,""),ROW()-(ROW()-H$2))),"")} | I8: {=IFERROR(INDEX(#REF!,SMALL(IF('ТРС общая'!$B8=#REF!,ROW(#REF!)-18,""),ROW()-(ROW()-I$2))),"")} | J8: {=IFERROR(INDEX(#REF!,SMALL(IF('ТРС общая'!$B8=#REF!,ROW(#REF!)-18,""),ROW()-(ROW()-J$2))),"")} | K8: {=IFERROR(INDEX(#REF!,SMALL(IF('ТРС общая'!$B8=#REF!,ROW(#REF!)-18,""),ROW()-(ROW()-K$2))),"")} | ... AM8: {=IFERROR(INDEX(#REF!,SMALL(IF('ТРС общая'!$B8=#REF!,ROW(#REF!)-18,""),ROW()-(ROW()-AM$2))),"")}
B9: 19 | C9: =COUNTIF('Расчет грейда'!$W:$W,'ТРС общая'!$B9) -> 0 | D9: {=IFERROR(INDEX(#REF!,SMALL(IF('ТРС общая'!$B9=#REF!,ROW(#REF!)-18,""),ROW()-(ROW()-D$2))),"")} | E9: {=IFERROR(INDEX(#REF!,SMALL(IF('ТРС общая'!$B9=#REF!,ROW(#REF!)-18,""),ROW()-(ROW()-E$2))),"")} | F9: {=IFERROR(INDEX(#REF!,SMALL(IF('ТРС общая'!$B9=#REF!,ROW(#REF!)-18,""),ROW()-(ROW()-F$2))),"")} | G9: {=IFERROR(INDEX(#REF!,SMALL(IF('ТРС общая'!$B9=#REF!,ROW(#REF!)-18,""),ROW()-(ROW()-G$2))),"")} | H9: {=IFERROR(INDEX(#REF!,SMALL(IF('ТРС общая'!$B9=#REF!,ROW(#REF!)-18,""),ROW()-(ROW()-H$2))),"")} | I9: {=IFERROR(INDEX(#REF!,SMALL(IF('ТРС общая'!$B9=#REF!,ROW(#REF!)-18,""),ROW()-(ROW()-I$2))),"")} | J9: {=IFERROR(INDEX(#REF!,SMALL(IF('ТРС общая'!$B9=#REF!,ROW(#REF!)-18,""),ROW()-(ROW()-J$2))),"")} | K9: {=IFERROR(INDEX(#REF!,SMALL(IF('ТРС общая'!$B9=#REF!,ROW(#REF!)-18,""),ROW()-(ROW()-K$2))),"")} | ... AM9: {=IFERROR(INDEX(#REF!,SMALL(IF('ТРС общая'!$B9=#REF!,ROW(#REF!)-18,""),ROW()-(ROW()-AM$2))),"")}
B10: 18 | C10: =COUNTIF('Расчет грейда'!$W:$W,'ТРС общая'!$B10) -> 0 | D10: {=IFERROR(INDEX(#REF!,SMALL(IF('ТРС общая'!$B10=#REF!,ROW(#REF!)-18,""),ROW()-(ROW()-D$2))),"")} | E10: {=IFERROR(INDEX(#REF!,SMALL(IF('ТРС общая'!$B10=#REF!,ROW(#REF!)-18,""),ROW()-(ROW()-E$2))),"")} | F10: {=IFERROR(INDEX(#REF!,SMALL(IF('ТРС общая'!$B10=#REF!,ROW(#REF!)-18,""),ROW()-(ROW()-F$2))),"")} | G10: {=IFERROR(INDEX(#REF!,SMALL(IF('ТРС общая'!$B10=#REF!,ROW(#REF!)-18,""),ROW()-(ROW()-G$2))),"")} | H10: {=IFERROR(INDEX(#REF!,SMALL(IF('ТРС общая'!$B10=#REF!,ROW(#REF!)-18,""),ROW()-(ROW()-H$2))),"")} | I10: {=IFERROR(INDEX(#REF!,SMALL(IF('ТРС общая'!$B10=#REF!,ROW(#REF!)-18,""),ROW()-(ROW()-I$2))),"")} | J10: {=IFERROR(INDEX(#REF!,SMALL(IF('ТРС общая'!$B10=#REF!,ROW(#REF!)-18,""),ROW()-(ROW()-J$2))),"")} | K10: {=IFERROR(INDEX(#REF!,SMALL(IF('ТРС общая'!$B10=#REF!,ROW(#REF!)-18,""),ROW()-(ROW()-K$2))),"")} | ... AM10: {=IFERROR(INDEX(#REF!,SMALL(IF('ТРС общая'!$B10=#REF!,ROW(#REF!)-18,""),ROW()-(ROW()-AM$2))),"")}
B11: 17 | C11: =COUNTIF('Расчет грейда'!$W:$W,'ТРС общая'!$B11) -> 0 | D11: {=IFERROR(INDEX(#REF!,SMALL(IF('ТРС общая'!$B11=#REF!,ROW(#REF!)-18,""),ROW()-(ROW()-D$2))),"")} | E11: {=IFERROR(INDEX(#REF!,SMALL(IF('ТРС общая'!$B11=#REF!,ROW(#REF!)-18,""),ROW()-(ROW()-E$2))),"")} | F11: {=IFERROR(INDEX(#REF!,SMALL(IF('ТРС общая'!$B11=#REF!,ROW(#REF!)-18,""),ROW()-(ROW()-F$2))),"")} | G11: {=IFERROR(INDEX(#REF!,SMALL(IF('ТРС общая'!$B11=#REF!,ROW(#REF!)-18,""),ROW()-(ROW()-G$2))),"")} | H11: {=IFERROR(INDEX(#REF!,SMALL(IF('ТРС общая'!$B11=#REF!,ROW(#REF!)-18,""),ROW()-(ROW()-H$2))),"")} | I11: {=IFERROR(INDEX(#REF!,SMALL(IF('ТРС общая'!$B11=#REF!,ROW(#REF!)-18,""),ROW()-(ROW()-I$2))),"")} | J11: {=IFERROR(INDEX(#REF!,SMALL(IF('ТРС общая'!$B11=#REF!,ROW(#REF!)-18,""),ROW()-(ROW()-J$2))),"")} | K11: {=IFERROR(INDEX(#REF!,SMALL(IF('ТРС общая'!$B11=#REF!,ROW(#REF!)-18,""),ROW()-(ROW()-K$2))),"")} | ... AM11: {=IFERROR(INDEX(#REF!,SMALL(IF('ТРС общая'!$B11=#REF!,ROW(#REF!)-18,""),ROW()-(ROW()-AM$2))),"")}
B12: 16 | C12: =COUNTIF('Расчет грейда'!$W:$W,'ТРС общая'!$B12) -> 0 | D12: {=IFERROR(INDEX(#REF!,SMALL(IF('ТРС общая'!$B12=#REF!,ROW(#REF!)-18,""),ROW()-(ROW()-D$2))),"")} | E12: {=IFERROR(INDEX(#REF!,SMALL(IF('ТРС общая'!$B12=#REF!,ROW(#REF!)-18,""),ROW()-(ROW()-E$2))),"")} | F12: {=IFERROR(INDEX(#REF!,SMALL(IF('ТРС общая'!$B12=#REF!,ROW(#REF!)-18,""),ROW()-(ROW()-F$2))),"")} | G12: {=IFERROR(INDEX(#REF!,SMALL(IF('ТРС общая'!$B12=#REF!,ROW(#REF!)-18,""),ROW()-(ROW()-G$2))),"")} | H12: {=IFERROR(INDEX(#REF!,SMALL(IF('ТРС общая'!$B12=#REF!,ROW(#REF!)-18,""),ROW()-(ROW()-H$2))),"")} | I12: {=IFERROR(INDEX(#REF!,SMALL(IF('ТРС общая'!$B12=#REF!,ROW(#REF!)-18,""),ROW()-(ROW()-I$2))),"")} | J12: {=IFERROR(INDEX(#REF!,SMALL(IF('ТРС общая'!$B12=#REF!,ROW(#REF!)-18,""),ROW()-(ROW()-J$2))),"")} | K12: {=IFERROR(INDEX(#REF!,SMALL(IF('ТРС общая'!$B12=#REF!,ROW(#REF!)-18,""),ROW()-(ROW()-K$2))),"")} | ... AM12: {=IFERROR(INDEX(#REF!,SMALL(IF('ТРС общая'!$B12=#REF!,ROW(#REF!)-18,""),ROW()-(ROW()-AM$2))),"")}
B13: 15 | C13: =COUNTIF('Расчет грейда'!$W:$W,'ТРС общая'!$B13) -> 0 | D13: {=IFERROR(INDEX(#REF!,SMALL(IF('ТРС общая'!$B13=#REF!,ROW(#REF!)-18,""),ROW()-(ROW()-D$2))),"")} | E13: {=IFERROR(INDEX(#REF!,SMALL(IF('ТРС общая'!$B13=#REF!,ROW(#REF!)-18,""),ROW()-(ROW()-E$2))),"")} | F13: {=IFERROR(INDEX(#REF!,SMALL(IF('ТРС общая'!$B13=#REF!,ROW(#REF!)-18,""),ROW()-(ROW()-F$2))),"")} | G13: {=IFERROR(INDEX(#REF!,SMALL(IF('ТРС общая'!$B13=#REF!,ROW(#REF!)-18,""),ROW()-(ROW()-G$2))),"")} | H13: {=IFERROR(INDEX(#REF!,SMALL(IF('ТРС общая'!$B13=#REF!,ROW(#REF!)-18,""),ROW()-(ROW()-H$2))),"")} | I13: {=IFERROR(INDEX(#REF!,SMALL(IF('ТРС общая'!$B13=#REF!,ROW(#REF!)-18,""),ROW()-(ROW()-I$2))),"")} | J13: {=IFERROR(INDEX(#REF!,SMALL(IF('ТРС общая'!$B13=#REF!,ROW(#REF!)-18,""),ROW()-(ROW()-J$2))),"")} | K13: {=IFERROR(INDEX(#REF!,SMALL(IF('ТРС общая'!$B13=#REF!,ROW(#REF!)-18,""),ROW()-(ROW()-K$2))),"")} | ... AM13: {=IFERROR(INDEX(#REF!,SMALL(IF('ТРС общая'!$B13=#REF!,ROW(#REF!)-18,""),ROW()-(ROW()-AM$2))),"")}
